#VRML_SIM R2025a utf8

EXTERNPROTO "https://raw.githubusercontent.com/cyberbotics/webots/R2023b/projects/objects/backgrounds/protos/TexturedBackground.proto"
EXTERNPROTO "https://raw.githubusercontent.com/cyberbotics/webots/R2023b/projects/objects/backgrounds/protos/TexturedBackgroundLight.proto"
EXTERNPROTO "https://raw.githubusercontent.com/cyberbotics/webots/R2023b/projects/objects/floors/protos/RectangleArena.proto"
EXTERNPROTO "https://raw.githubusercontent.com/cyberbotics/webots/R2023b/projects/appearances/protos/Parquetry.proto"
EXTERNPROTO "https://raw.githubusercontent.com/cyberbotics/webots/R2025a/projects/objects/apartment_structure/protos/Wall.proto"
EXTERNPROTO "https://raw.githubusercontent.com/cyberbotics/webots/R2025a/projects/appearances/protos/Roughcast.proto"

WorldInfo {
}
Viewpoint {
  orientation -0.5773502691896258 0.5773502691896258 0.5773502691896258 2.0944
  position 0.000296782024572402 8.818842725714247e-06 3.4439124808416737
}
TexturedBackground {
}
TexturedBackgroundLight {
}
RectangleArena {
  floorSize 2 1.5
  floorTileSize 0.2 0.2
  floorAppearance Parquetry {
    type "dark strip"
    colorOverride 0 1 0
  }
}
DEF robot1 Robot {
  translation 0.359995 0.309967 0.09
  rotation 0 0 -1 -5.307179586466759e-06
  children [
    Camera {
      translation 0.06 0 0.004
      children [
        Shape {
          appearance PBRAppearance {
            transparency 1
          }
          geometry Box {
            size 0.005 0.005 0.006
          }
        }
      ]
      name "cam"
      recognition Recognition {
        frameColor 1 1 0
      }
    }
    DEF mark Solid {
      translation 0.005 0 0.035
      rotation 0 0 1 -1.5707996938995747
      children [
        Shape {
          appearance PBRAppearance {
            baseColor 1 0 0
            metalness 0
          }
          geometry Plane {
            size 0.07 0.07
          }
        }
      ]
      name "solid(5)"
    }
    Emitter {
      channel 1
    }
    Receiver {
      channel 1
    }
    InertialUnit {
      translation 0.021 0 0.043
      children [
        Shape {
          appearance PBRAppearance {
            baseColor 0 0.5 1
            transparency 1
          }
          geometry Box {
            size 0.01 0.01 0.01
          }
        }
      ]
      name "imu"
    }
    GPS {
      children [
        Solid {
          translation 0 0 0.041
          children [
            Shape {
              appearance PBRAppearance {
                transparency 1
              }
              geometry Cylinder {
                height 0.013
                radius 0.006
              }
            }
          ]
        }
      ]
      name "global"
    }
    DEF ds_belakang DistanceSensor {
      translation -0.0614 0 0.008
      rotation 0 0 1 3.14159
      children [
        DEF belakang Shape {
          appearance PBRAppearance {
            transparency 1
          }
          geometry Box {
            size 0.002 0.002 0.002
          }
        }
      ]
      name "ds_belakang"
      boundingObject USE belakang
      physics Physics {
      }
    }
    DEF ds_kiri DistanceSensor {
      translation -0.0089 0.0279 0.0296
      rotation 0 0 1 1.5708
      children [
        DEF kiri Shape {
          appearance PBRAppearance {
            transparency 1
          }
          geometry Box {
            size 0.002 0.002 0.002
          }
        }
      ]
      name "ds_kiri"
      boundingObject USE kiri
      physics Physics {
      }
    }
    DEF ds_kanan DistanceSensor {
      translation -0.0089 -0.0275 0.0296
      rotation 0 0 1 -1.5707953071795862
      children [
        DEF kanan Shape {
          appearance PBRAppearance {
            transparency 1
          }
          geometry Box {
            size 0.002 0.002 0.002
          }
        }
      ]
      name "ds_kanan"
      boundingObject USE kanan
      physics Physics {
      }
    }
    DEF ds_depan DistanceSensor {
      translation 0.039 0 0.03
      children [
        DEF depan Shape {
          appearance PBRAppearance {
            transparency 1
          }
          geometry Box {
            size 0.002 0.002 0.002
          }
        }
      ]
      name "ds_depan"
      boundingObject USE depan
      physics Physics {
      }
    }
    DEF motor_kanan_belakang HingeJoint {
      jointParameters HingeJointParameters {
        axis 0 1 0
        anchor -0.0457 -0.0421 -0.02683
      }
      device [
        RotationalMotor {
          name "motor_kanan_belakang"
        }
        PositionSensor {
          name "encoder_4"
        }
      ]
      endPoint Solid {
        translation -0.04570000000000008 -0.042100000000000026 -0.026829999999999996
        rotation 0.9999999999999991 2.969474578465478e-08 -3.030140525816414e-08 1.5707999970234283
        children [
          DEF roda Shape {
            appearance PBRAppearance {
              transparency 1
            }
            geometry Cylinder {
              height 0.016
              radius 0.02
            }
          }
          CadShape {
            url [
              "../model/new design/kiri_belakang.obj"
            ]
          }
        ]
        name "solid(4)"
        boundingObject USE roda
        physics Physics {
        }
      }
    }
    DEF motor_kiri_belakang HingeJoint {
      jointParameters HingeJointParameters {
        axis 0 1 0
        anchor -0.0457 0.04255 -0.02683
      }
      device [
        RotationalMotor {
          name "motor_kiri_belakang"
        }
        PositionSensor {
          name "encoder_3"
        }
      ]
      endPoint Solid {
        translation -0.045700000000000005 0.04255 -0.026830000000000003
        rotation 0.9999999999999998 -1.9788313652998278e-08 -1.6395574335719573e-08 4.7123900006441914
        children [
          DEF roda Shape {
            appearance PBRAppearance {
              transparency 1
            }
            geometry Cylinder {
              height 0.016
              radius 0.02
            }
          }
          CadShape {
            url [
              "../model/new design/kiri_belakang.obj"
            ]
          }
        ]
        name "solid(3)"
        boundingObject USE roda
        physics Physics {
        }
      }
    }
    DEF motor_kiri_depan HingeJoint {
      jointParameters HingeJointParameters {
        axis 0 1 0
        anchor 0.02774 0.04255 -0.02683
      }
      device [
        RotationalMotor {
          name "motor_kiri_depan"
        }
        PositionSensor {
          name "encoder_2"
        }
      ]
      endPoint Solid {
        translation 0.027739999999999997 0.04255 -0.026830000000000014
        rotation 1 5.232983392724199e-09 8.670595327961642e-09 4.7123900007965265
        children [
          DEF roda Shape {
            appearance PBRAppearance {
              transparency 1
            }
            geometry Cylinder {
              height 0.016
              radius 0.02
            }
          }
          CadShape {
            url [
              "../model/new design/kiri_depan.obj"
            ]
          }
        ]
        name "solid(2)"
        boundingObject USE roda
        physics Physics {
        }
      }
    }
    DEF motor_kanan_depan HingeJoint {
      jointParameters HingeJointParameters {
        axis 0 1 0
        anchor 0.02774 -0.0421 -0.02683
      }
      device [
        RotationalMotor {
          name "motor_kanan_depan"
        }
        PositionSensor {
          name "encoder_1"
        }
      ]
      endPoint Solid {
        translation 0.02773999999999976 -0.042100000000000026 -0.02683
        rotation 1 3.3520365225784843e-10 -1.0581822541895836e-09 1.570789996806691
        children [
          DEF roda Shape {
            appearance PBRAppearance {
              transparency 1
            }
            geometry Cylinder {
              height 0.016
              radius 0.02
            }
          }
          CadShape {
            url [
              "../model/new design/kanan_depan.obj"
            ]
          }
        ]
        name "solid(1)"
        boundingObject USE roda
        physics Physics {
        }
      }
    }
    Solid {
      translation -0.0035 0.000126 -0.00627
      children [
        CadShape {
          url [
            "../model/new design/body.obj"
          ]
        }
      ]
    }
    Pose {
      children [
        DEF body Shape {
          appearance PBRAppearance {
            transparency 1
          }
          geometry Box {
            size 0.125 0.065 0.076
          }
        }
      ]
    }
  ]
  name "robot1"
  boundingObject USE body
  physics Physics {
  }
  controller "robot_controller_node"
  supervisor TRUE
}
DEF robot2 Robot {
  translation -0.89 -0.68003 0.09
  rotation 0 0 1 5.307156870259904e-06
  children [
    DEF mark Solid {
      translation 0.0044 0 0.035
      rotation 0 0 1 -1.5708003061004252
      children [
        Shape {
          appearance PBRAppearance {
            baseColor 1 0 1
            metalness 0
          }
          geometry Plane {
            size 0.07 0.07
          }
        }
      ]
      name "solid(5)"
      recognitionColors [
        0 0 1
      ]
    }
    Camera {
      translation 0.06 0 0.004
      children [
        Shape {
          appearance PBRAppearance {
            transparency 1
          }
          geometry Box {
            size 0.005 0.005 0.006
          }
        }
      ]
      name "cam"
      recognition Recognition {
        frameColor 1 1 0
      }
    }
    Emitter {
      channel 1
    }
    Receiver {
      channel 1
    }
    InertialUnit {
      translation 0.021 0 0.043
      children [
        Shape {
          appearance PBRAppearance {
            baseColor 0 0.5 1
            transparency 1
          }
          geometry Box {
            size 0.01 0.01 0.01
          }
        }
      ]
      name "imu"
    }
    GPS {
      children [
        Solid {
          translation 0 0 0.041
          children [
            Shape {
              appearance PBRAppearance {
                transparency 1
              }
              geometry Cylinder {
                height 0.013
                radius 0.006
              }
            }
          ]
        }
      ]
      name "global"
    }
    DEF ds_belakang DistanceSensor {
      translation -0.0614 0 0.008
      rotation 0 0 1 3.14159
      children [
        DEF belakang Shape {
          appearance PBRAppearance {
            transparency 1
          }
          geometry Box {
            size 0.002 0.002 0.002
          }
        }
      ]
      name "ds_belakang"
      boundingObject USE belakang
      physics Physics {
      }
    }
    DEF ds_kiri DistanceSensor {
      translation -0.0089 0.0279 0.0296
      rotation 0 0 1 1.5708
      children [
        DEF kiri Shape {
          appearance PBRAppearance {
            transparency 1
          }
          geometry Box {
            size 0.002 0.002 0.002
          }
        }
      ]
      name "ds_kiri"
      boundingObject USE kiri
      physics Physics {
      }
    }
    DEF ds_kanan DistanceSensor {
      translation -0.0089 -0.0275 0.0296
      rotation 0 0 1 -1.5707953071795862
      children [
        DEF kanan Shape {
          appearance PBRAppearance {
            transparency 1
          }
          geometry Box {
            size 0.002 0.002 0.002
          }
        }
      ]
      name "ds_kanan"
      boundingObject USE kanan
      physics Physics {
      }
    }
    DEF ds_depan DistanceSensor {
      translation 0.039 0 0.03
      children [
        DEF depan Shape {
          appearance PBRAppearance {
            transparency 1
          }
          geometry Box {
            size 0.002 0.002 0.002
          }
        }
      ]
      name "ds_depan"
      boundingObject USE depan
      physics Physics {
      }
    }
    DEF motor_kanan_belakang HingeJoint {
      jointParameters HingeJointParameters {
        axis 0 1 0
        anchor -0.0457 -0.0421 -0.02683
      }
      device [
        RotationalMotor {
          name "motor_kanan_belakang"
        }
        PositionSensor {
          name "encoder_4"
        }
      ]
      endPoint Solid {
        translation -0.04569999999999996 -0.04210000000000008 -0.026829999999999993
        rotation 0.9999999999999991 2.945102371654608e-08 -3.005768337497837e-08 1.5707999970234647
        children [
          DEF roda Shape {
            appearance PBRAppearance {
              transparency 1
            }
            geometry Cylinder {
              height 0.016
              radius 0.02
            }
          }
          CadShape {
            url [
              "../model/new design/kiri_belakang.obj"
            ]
          }
        ]
        name "solid(4)"
        boundingObject USE roda
        physics Physics {
        }
      }
    }
    DEF motor_kiri_belakang HingeJoint {
      jointParameters HingeJointParameters {
        axis 0 1 0
        anchor -0.0457 0.04255 -0.02683
      }
      device [
        RotationalMotor {
          name "motor_kiri_belakang"
        }
        PositionSensor {
          name "encoder_3"
        }
      ]
      endPoint Solid {
        translation -0.045700000000000005 0.04255 -0.02683
        rotation 0.9999999999999998 -1.9577590154566715e-08 -1.61848508952716e-08 4.712390000644207
        children [
          DEF roda Shape {
            appearance PBRAppearance {
              transparency 1
            }
            geometry Cylinder {
              height 0.016
              radius 0.02
            }
          }
          CadShape {
            url [
              "../model/new design/kiri_belakang.obj"
            ]
          }
        ]
        name "solid(3)"
        boundingObject USE roda
        physics Physics {
        }
      }
    }
    DEF motor_kiri_depan HingeJoint {
      jointParameters HingeJointParameters {
        axis 0 1 0
        anchor 0.02774 0.04255 -0.02683
      }
      device [
        RotationalMotor {
          name "motor_kiri_depan"
        }
        PositionSensor {
          name "encoder_2"
        }
      ]
      endPoint Solid {
        translation 0.027739999999999994 0.04255 -0.02683000000000001
        rotation 1 5.273470842857918e-09 8.711083070425642e-09 4.712390000796518
        children [
          DEF roda Shape {
            appearance PBRAppearance {
              transparency 1
            }
            geometry Cylinder {
              height 0.016
              radius 0.02
            }
          }
          CadShape {
            url [
              "../model/new design/kiri_depan.obj"
            ]
          }
        ]
        name "solid(2)"
        boundingObject USE roda
        physics Physics {
        }
      }
    }
    DEF motor_kanan_depan HingeJoint {
      jointParameters HingeJointParameters {
        axis 0 1 0
        anchor 0.02774 -0.0421 -0.02683
      }
      device [
        RotationalMotor {
          name "motor_kanan_depan"
        }
        PositionSensor {
          name "encoder_1"
        }
      ]
      endPoint Solid {
        translation 0.027739999999999987 -0.042100000000000026 -0.026830000000000007
        rotation 1 3.0610090190566556e-10 -1.029081359250882e-09 1.570789996806724
        children [
          DEF roda Shape {
            appearance PBRAppearance {
              transparency 1
            }
            geometry Cylinder {
              height 0.016
              radius 0.02
            }
          }
          CadShape {
            url [
              "../model/new design/kanan_depan.obj"
            ]
          }
        ]
        name "solid(1)"
        boundingObject USE roda
        physics Physics {
        }
      }
    }
    Solid {
      translation -0.0035 0.000126 -0.00627
      children [
        CadShape {
          url [
            "../model/new design/body.obj"
          ]
        }
      ]
    }
    Pose {
      children [
        DEF body Shape {
          appearance PBRAppearance {
            transparency 1
          }
          geometry Box {
            size 0.125 0.065 0.076
          }
        }
      ]
    }
  ]
  name "robot2"
  boundingObject USE body
  physics Physics {
  }
  controller "<none>"
  supervisor TRUE
}
DEF target Robot {
  translation -0.49 0.55 0.05
  children [
    GPS {
      children [
        Solid {
          translation 0 0 0.041
          children [
            Shape {
              appearance PBRAppearance {
                transparency 1
              }
              geometry Cylinder {
                height 0.013
                radius 0.006
              }
            }
          ]
        }
      ]
      name "global"
    }
    Receiver {
      channel 1
    }
    Emitter {
      channel 1
    }
    Shape {
      appearance PBRAppearance {
        baseColor 0 0 1
        metalness 0
      }
      geometry Box {
        size 0.1 0.1 0.1
      }
    }
  ]
  name "target"
  controller "<none>"
  supervisor TRUE
}
Robot {
  children [
    Solid {
      translation 0 0 0.01
      name "maze"
    }
  ]
  name "maze"
  controller "<none>"
  supervisor TRUE
}
DEF camera Robot {
  translation 0 0 2.5
  rotation 0 0 1 1.5708
  children [
    DEF camera Camera {
      rotation 0 1 0 1.5708003061004252
      children [
        Shape {
          appearance PBRAppearance {
            transparency 1
            metalness 0
          }
          geometry Box {
            size 0.1 0.1 0.1
          }
        }
      ]
      width 800
      height 600
      recognition Recognition {
      }
    }
  ]
  name "camera"
  controller "<extern>"
  supervisor TRUE
}
Wall {
  translation 0 0.17 0
  size 0.15 1.16 0.1
  appearance Roughcast {
    colorOverride 1 1 0
    textureTransform TextureTransform {
      scale 2.4 1
    }
  }
}
