#VRML_SIM R2023b utf8

EXTERNPROTO "https://raw.githubusercontent.com/cyberbotics/webots/R2023b/projects/objects/backgrounds/protos/TexturedBackground.proto"
EXTERNPROTO "https://raw.githubusercontent.com/cyberbotics/webots/R2023b/projects/objects/backgrounds/protos/TexturedBackgroundLight.proto"
EXTERNPROTO "https://raw.githubusercontent.com/cyberbotics/webots/R2023b/projects/objects/floors/protos/RectangleArena.proto"

WorldInfo {
}
Viewpoint {
  orientation -0.15729286085825522 -0.13005358970954728 0.978950979225562 4.132853592763744
  position -0.4424526166661453 1.245754077495991 0.34925010002597817
}
TexturedBackground {
}
TexturedBackgroundLight {
}
RectangleArena {
  floorSize 4 4
}
DEF robot1 Robot {
  translation -0.930003 0.62997 0.09
  rotation 0 0 1 5.307156870259904e-06
  children [
    DEF leader_mark Solid {
      translation 0 0 0.049
      children [
        Shape {
          appearance PBRAppearance {
            baseColor 1 0 0
            metalness 0
          }
          geometry Box {
            size 0.03 0.03 0.03
          }
        }
      ]
      name "solid(5)"
      recognitionColors [
        1 0 0
      ]
    }
    Camera {
      translation 0.06 0 0.004
      children [
        Shape {
          appearance PBRAppearance {
            transparency 1
          }
          geometry Box {
            size 0.005 0.005 0.006
          }
        }
      ]
      name "cam"
      recognition Recognition {
        frameColor 1 1 0
      }
    }
    Emitter {
      channel 1
    }
    Receiver {
      channel 1
    }
    InertialUnit {
      translation 0.021 0 0.043
      children [
        Shape {
          appearance PBRAppearance {
            baseColor 0 0.5 1
            transparency 1
          }
          geometry Box {
            size 0.01 0.01 0.01
          }
        }
      ]
      name "imu"
    }
    GPS {
      children [
        Solid {
          translation 0 0 0.041
          children [
            Shape {
              appearance PBRAppearance {
                transparency 1
              }
              geometry Cylinder {
                height 0.013
                radius 0.006
              }
            }
          ]
        }
      ]
      name "global"
    }
    DEF ds_belakang DistanceSensor {
      translation -0.0614 0 0.008
      rotation 0 0 1 3.14159
      children [
        DEF belakang Shape {
          appearance PBRAppearance {
            transparency 1
          }
          geometry Box {
            size 0.002 0.002 0.002
          }
        }
      ]
      name "ds_belakang"
      boundingObject USE belakang
      physics Physics {
      }
    }
    DEF ds_kiri DistanceSensor {
      translation -0.0089 0.0279 0.0296
      rotation 0 0 1 1.5708
      children [
        DEF kiri Shape {
          appearance PBRAppearance {
            transparency 1
          }
          geometry Box {
            size 0.002 0.002 0.002
          }
        }
      ]
      name "ds_kiri"
      boundingObject USE kiri
      physics Physics {
      }
    }
    DEF ds_kanan DistanceSensor {
      translation -0.0089 -0.0275 0.0296
      rotation 0 0 1 -1.5707953071795862
      children [
        DEF kanan Shape {
          appearance PBRAppearance {
            transparency 1
          }
          geometry Box {
            size 0.002 0.002 0.002
          }
        }
      ]
      name "ds_kanan"
      boundingObject USE kanan
      physics Physics {
      }
    }
    DEF ds_depan DistanceSensor {
      translation 0.039 0 0.03
      children [
        DEF depan Shape {
          appearance PBRAppearance {
            transparency 1
          }
          geometry Box {
            size 0.002 0.002 0.002
          }
        }
      ]
      name "ds_depan"
      boundingObject USE depan
      physics Physics {
      }
    }
    DEF motor_kanan_belakang HingeJoint {
      jointParameters HingeJointParameters {
        axis 0 1 0
        anchor -0.0457 -0.0421 -0.02683
      }
      device [
        RotationalMotor {
          name "motor_kanan_belakang"
        }
        PositionSensor {
          name "encoder_4"
        }
      ]
      endPoint Solid {
        translation -0.045699999999999984 -0.0421 -0.026829999999999993
        rotation 0.9999999999999992 2.9694744783722082e-08 -3.030140533666802e-08 1.570799997023469
        children [
          DEF roda Shape {
            appearance PBRAppearance {
              transparency 1
            }
            geometry Cylinder {
              height 0.016
              radius 0.02
            }
          }
          CadShape {
            url [
              "../../../../../../../../Downloads/simulation design/new design/tes1.obj"
            ]
          }
        ]
        name "solid(4)"
        boundingObject USE roda
        physics Physics {
        }
      }
    }
    DEF motor_kiri_belakang HingeJoint {
      jointParameters HingeJointParameters {
        axis 0 1 0
        anchor -0.0457 0.04255 -0.02683
      }
      device [
        RotationalMotor {
          name "motor_kiri_belakang"
        }
        PositionSensor {
          name "encoder_3"
        }
      ]
      endPoint Solid {
        translation -0.045700000000000005 0.04255 -0.02683
        rotation 0.9999999999999998 -1.9788314143652575e-08 -1.6395574669364524e-08 4.712390000644207
        children [
          DEF roda Shape {
            appearance PBRAppearance {
              transparency 1
            }
            geometry Cylinder {
              height 0.016
              radius 0.02
            }
          }
          CadShape {
            url [
              "../../../../../../../../Downloads/simulation design/new design/kiri_belakang.obj"
            ]
          }
        ]
        name "solid(3)"
        boundingObject USE roda
        physics Physics {
        }
      }
    }
    DEF motor_kiri_depan HingeJoint {
      jointParameters HingeJointParameters {
        axis 0 1 0
        anchor 0.02774 0.04255 -0.02683
      }
      device [
        RotationalMotor {
          name "motor_kiri_depan"
        }
        PositionSensor {
          name "encoder_2"
        }
      ]
      endPoint Solid {
        translation 0.027739999999999994 0.04255 -0.02683000000000001
        rotation 1 5.232982509546716e-09 8.670594778428961e-09 4.712390000796518
        children [
          DEF roda Shape {
            appearance PBRAppearance {
              transparency 1
            }
            geometry Cylinder {
              height 0.016
              radius 0.02
            }
          }
          CadShape {
            url [
              "../../../../../../../../Downloads/simulation design/new design/kiri_depan.obj"
            ]
          }
        ]
        name "solid(2)"
        boundingObject USE roda
        physics Physics {
        }
      }
    }
    DEF motor_kanan_depan HingeJoint {
      jointParameters HingeJointParameters {
        axis 0 1 0
        anchor 0.02774 -0.0421 -0.02683
      }
      device [
        RotationalMotor {
          name "motor_kanan_depan"
        }
        PositionSensor {
          name "encoder_1"
        }
      ]
      endPoint Solid {
        translation 0.027739999999999997 -0.0421 -0.026830000000000003
        rotation 1 3.883813409268065e-10 -1.1113612774413419e-09 1.5707899968067291
        children [
          DEF roda Shape {
            appearance PBRAppearance {
              transparency 1
            }
            geometry Cylinder {
              height 0.016
              radius 0.02
            }
          }
          CadShape {
            url [
              "../../../../../../../../Downloads/simulation design/new design/kanan_depan.obj"
            ]
          }
        ]
        name "solid(1)"
        boundingObject USE roda
        physics Physics {
        }
      }
    }
    Solid {
      translation -0.0035 0.000126 -0.00627
      children [
        CadShape {
          url [
            "../../../../../../../../Downloads/simulation design/new design/body.obj"
          ]
        }
      ]
    }
    Pose {
      children [
        DEF body Shape {
          appearance PBRAppearance {
            transparency 1
          }
          geometry Box {
            size 0.125 0.065 0.076
          }
        }
      ]
    }
  ]
  name "robot1"
  boundingObject USE body
  physics Physics {
  }
  controller "leader"
  supervisor TRUE
}
DEF robot2 Robot {
  translation 0.7 -0.530007 0.11
  rotation 0 0 -1 -5.307179586466759e-06
  children [
    Camera {
      translation 0.06 0 0.004
      children [
        Shape {
          appearance PBRAppearance {
            transparency 1
          }
          geometry Box {
            size 0.005 0.005 0.006
          }
        }
      ]
      name "cam"
      recognition Recognition {
      }
    }
    Emitter {
      channel 1
    }
    Receiver {
      channel 1
    }
    InertialUnit {
      translation 0.021 0 0.043
      children [
        Shape {
          appearance PBRAppearance {
            baseColor 0 0.5 1
            transparency 1
          }
          geometry Box {
            size 0.01 0.01 0.01
          }
        }
      ]
      name "imu"
    }
    GPS {
      children [
        Solid {
          translation 0 0 0.041
          children [
            Shape {
              appearance PBRAppearance {
                transparency 1
              }
              geometry Cylinder {
                height 0.013
                radius 0.006
              }
            }
          ]
        }
      ]
      name "global"
    }
    DEF ds_belakang DistanceSensor {
      translation -0.0614 0 0.008
      rotation 0 0 1 3.14159
      children [
        DEF belakang Shape {
          appearance PBRAppearance {
            transparency 1
          }
          geometry Box {
            size 0.002 0.002 0.002
          }
        }
      ]
      name "ds_belakang"
      boundingObject USE belakang
      physics Physics {
      }
    }
    DEF ds_kiri DistanceSensor {
      translation -0.0089 0.0279 0.0296
      rotation 0 0 1 1.5708
      children [
        DEF kiri Shape {
          appearance PBRAppearance {
            transparency 1
          }
          geometry Box {
            size 0.002 0.002 0.002
          }
        }
      ]
      name "ds_kiri"
      boundingObject USE kiri
      physics Physics {
      }
    }
    DEF ds_kanan DistanceSensor {
      translation -0.0089 -0.0275 0.0296
      rotation 0 0 1 -1.5707953071795862
      children [
        DEF kanan Shape {
          appearance PBRAppearance {
            transparency 1
          }
          geometry Box {
            size 0.002 0.002 0.002
          }
        }
      ]
      name "ds_kanan"
      boundingObject USE kanan
      physics Physics {
      }
    }
    DEF ds_depan DistanceSensor {
      translation 0.039 0 0.03
      children [
        DEF depan Shape {
          appearance PBRAppearance {
            transparency 1
          }
          geometry Box {
            size 0.002 0.002 0.002
          }
        }
      ]
      name "ds_depan"
      boundingObject USE depan
      physics Physics {
      }
    }
    DEF motor_kanan_belakang HingeJoint {
      jointParameters HingeJointParameters {
        axis 0 1 0
        anchor -0.048 -0.0403 -0.0308
      }
      device [
        RotationalMotor {
          name "motor_kanan_belakang"
        }
        PositionSensor {
          name "encoder_4"
        }
      ]
      endPoint Solid {
        translation -0.048 -0.0403 -0.0308
        rotation 1 7.065403087751572e-16 0 1.570799999999998
        children [
          DEF roda Shape {
            appearance PBRAppearance {
              transparency 1
            }
            geometry Cylinder {
              height 0.018
              radius 0.023
            }
          }
          CadShape {
            url [
              "../../../../../../../../Downloads/swarm_obj_webots/roda_kanan_belakang.obj"
            ]
          }
        ]
        name "solid(4)"
        boundingObject USE roda
        physics Physics {
        }
      }
    }
    DEF motor_kiri_belakang HingeJoint {
      jointParameters HingeJointParameters {
        axis 0 1 0
        anchor -0.048 0.04 -0.0308
      }
      device [
        RotationalMotor {
          name "motor_kiri_belakang"
        }
        PositionSensor {
          name "encoder_3"
        }
      ]
      endPoint Solid {
        translation -0.048 0.04 -0.0308
        rotation -0.9999999999999999 3.925233147823865e-17 3.925233147823865e-17 1.5707953071795813
        children [
          DEF roda Shape {
            appearance PBRAppearance {
              transparency 1
            }
            geometry Cylinder {
              height 0.018
              radius 0.023
            }
          }
          CadShape {
            url [
              "../../../../../../../../Downloads/swarm_obj_webots/roda_kiri_belakang.obj"
            ]
          }
        ]
        name "solid(3)"
        boundingObject USE roda
        physics Physics {
        }
      }
    }
    DEF motor_kiri_depan HingeJoint {
      jointParameters HingeJointParameters {
        axis 0 1 0
        anchor 0.0251 0.04 -0.0308
      }
      device [
        RotationalMotor {
          name "motor_kiri_depan"
        }
        PositionSensor {
          name "encoder_2"
        }
      ]
      endPoint Solid {
        translation 0.0251 0.04 -0.0308
        rotation -0.9999999999999999 -1.177569944347159e-16 7.850466295647729e-17 1.5707953071795813
        children [
          DEF roda Shape {
            appearance PBRAppearance {
              transparency 1
            }
            geometry Cylinder {
              height 0.018
              radius 0.023
            }
          }
          CadShape {
            url [
              "../../../../../../../../Downloads/swarm_obj_webots/roda_kiri_depan.obj"
            ]
          }
        ]
        name "solid(2)"
        boundingObject USE roda
        physics Physics {
        }
      }
    }
    DEF motor_kanan_depan HingeJoint {
      jointParameters HingeJointParameters {
        axis 0 1 0
        anchor 0.0251 -0.0403 -0.0308
      }
      device [
        RotationalMotor {
          name "motor_kanan_depan"
        }
        PositionSensor {
          name "encoder_1"
        }
      ]
      endPoint Solid {
        translation 0.0251 -0.0403 -0.0308
        rotation 1 3.925243563834555e-17 0 1.5707899999999981
        children [
          DEF roda Shape {
            appearance PBRAppearance {
              transparency 1
            }
            geometry Cylinder {
              height 0.018
              radius 0.023
            }
          }
          CadShape {
            url [
              "../../../../../../../../Downloads/swarm_obj_webots/roda_kanan_depan.obj"
            ]
          }
        ]
        name "solid(1)"
        boundingObject USE roda
        physics Physics {
        }
      }
    }
    Solid {
      translation -0.0035 0.000126 -0.00627
      children [
        CadShape {
          url [
            "../../../../../../../../Downloads/swarm_obj_webots/body.obj"
          ]
        }
      ]
    }
    Pose {
      children [
        DEF body Shape {
          appearance PBRAppearance {
            transparency 1
          }
          geometry Box {
            size 0.125 0.058 0.077
          }
        }
      ]
    }
  ]
  name "robot2"
  boundingObject USE body
  physics Physics {
  }
  controller "follower"
}
DEF robot2 Robot {
  translation 0.799999 -0.270007 0.21
  rotation 0 0 -1 -5.307179586466759e-06
  children [
    Camera {
      translation 0.06 0 0.004
      children [
        Shape {
          appearance PBRAppearance {
            transparency 1
          }
          geometry Box {
            size 0.005 0.005 0.006
          }
        }
      ]
      name "cam"
      recognition Recognition {
      }
    }
    Emitter {
      channel 1
    }
    Receiver {
      channel 1
    }
    InertialUnit {
      translation 0.021 0 0.043
      children [
        Shape {
          appearance PBRAppearance {
            baseColor 0 0.5 1
            transparency 1
          }
          geometry Box {
            size 0.01 0.01 0.01
          }
        }
      ]
      name "imu"
    }
    GPS {
      children [
        Solid {
          translation 0 0 0.041
          children [
            Shape {
              appearance PBRAppearance {
                transparency 1
              }
              geometry Cylinder {
                height 0.013
                radius 0.006
              }
            }
          ]
        }
      ]
      name "global"
    }
    DEF ds_belakang DistanceSensor {
      translation -0.0614 0 0.008
      rotation 0 0 1 3.14159
      children [
        DEF belakang Shape {
          appearance PBRAppearance {
            transparency 1
          }
          geometry Box {
            size 0.002 0.002 0.002
          }
        }
      ]
      name "ds_belakang"
      boundingObject USE belakang
      physics Physics {
      }
    }
    DEF ds_kiri DistanceSensor {
      translation -0.0089 0.0279 0.0296
      rotation 0 0 1 1.5708
      children [
        DEF kiri Shape {
          appearance PBRAppearance {
            transparency 1
          }
          geometry Box {
            size 0.002 0.002 0.002
          }
        }
      ]
      name "ds_kiri"
      boundingObject USE kiri
      physics Physics {
      }
    }
    DEF ds_kanan DistanceSensor {
      translation -0.0089 -0.0275 0.0296
      rotation 0 0 1 -1.5707953071795862
      children [
        DEF kanan Shape {
          appearance PBRAppearance {
            transparency 1
          }
          geometry Box {
            size 0.002 0.002 0.002
          }
        }
      ]
      name "ds_kanan"
      boundingObject USE kanan
      physics Physics {
      }
    }
    DEF ds_depan DistanceSensor {
      translation 0.039 0 0.03
      children [
        DEF depan Shape {
          appearance PBRAppearance {
            transparency 1
          }
          geometry Box {
            size 0.002 0.002 0.002
          }
        }
      ]
      name "ds_depan"
      boundingObject USE depan
      physics Physics {
      }
    }
    DEF motor_kanan_belakang HingeJoint {
      jointParameters HingeJointParameters {
        axis 0 1 0
        anchor -0.048 -0.0403 -0.0308
      }
      device [
        RotationalMotor {
          name "motor_kanan_belakang"
        }
        PositionSensor {
          name "encoder_4"
        }
      ]
      endPoint Solid {
        translation -0.048 -0.0403 -0.0308
        rotation 1 7.065403087751572e-16 0 1.570799999999998
        children [
          DEF roda Shape {
            appearance PBRAppearance {
              transparency 1
            }
            geometry Cylinder {
              height 0.018
              radius 0.023
            }
          }
          CadShape {
            url [
              "../../../../../../../../Downloads/swarm_obj_webots/roda_kanan_belakang.obj"
            ]
          }
        ]
        name "solid(4)"
        boundingObject USE roda
        physics Physics {
        }
      }
    }
    DEF motor_kiri_belakang HingeJoint {
      jointParameters HingeJointParameters {
        axis 0 1 0
        anchor -0.048 0.04 -0.0308
      }
      device [
        RotationalMotor {
          name "motor_kiri_belakang"
        }
        PositionSensor {
          name "encoder_3"
        }
      ]
      endPoint Solid {
        translation -0.048 0.04 -0.0308
        rotation -0.9999999999999999 3.925233147823865e-17 3.925233147823865e-17 1.5707953071795813
        children [
          DEF roda Shape {
            appearance PBRAppearance {
              transparency 1
            }
            geometry Cylinder {
              height 0.018
              radius 0.023
            }
          }
          CadShape {
            url [
              "../../../../../../../../Downloads/swarm_obj_webots/roda_kiri_belakang.obj"
            ]
          }
        ]
        name "solid(3)"
        boundingObject USE roda
        physics Physics {
        }
      }
    }
    DEF motor_kiri_depan HingeJoint {
      jointParameters HingeJointParameters {
        axis 0 1 0
        anchor 0.0251 0.04 -0.0308
      }
      device [
        RotationalMotor {
          name "motor_kiri_depan"
        }
        PositionSensor {
          name "encoder_2"
        }
      ]
      endPoint Solid {
        translation 0.0251 0.04 -0.0308
        rotation -0.9999999999999999 -1.177569944347159e-16 7.850466295647729e-17 1.5707953071795813
        children [
          DEF roda Shape {
            appearance PBRAppearance {
              transparency 1
            }
            geometry Cylinder {
              height 0.018
              radius 0.023
            }
          }
          CadShape {
            url [
              "../../../../../../../../Downloads/swarm_obj_webots/roda_kiri_depan.obj"
            ]
          }
        ]
        name "solid(2)"
        boundingObject USE roda
        physics Physics {
        }
      }
    }
    DEF motor_kanan_depan HingeJoint {
      jointParameters HingeJointParameters {
        axis 0 1 0
        anchor 0.0251 -0.0403 -0.0308
      }
      device [
        RotationalMotor {
          name "motor_kanan_depan"
        }
        PositionSensor {
          name "encoder_1"
        }
      ]
      endPoint Solid {
        translation 0.0251 -0.0403 -0.0308
        rotation 1 3.925243563834555e-17 0 1.5707899999999981
        children [
          DEF roda Shape {
            appearance PBRAppearance {
              transparency 1
            }
            geometry Cylinder {
              height 0.018
              radius 0.023
            }
          }
          CadShape {
            url [
              "../../../../../../../../Downloads/swarm_obj_webots/roda_kanan_depan.obj"
            ]
          }
        ]
        name "solid(1)"
        boundingObject USE roda
        physics Physics {
        }
      }
    }
    Solid {
      translation -0.0035 0.000126 -0.00627
      children [
        CadShape {
          url [
            "../../../../../../../../Downloads/swarm_obj_webots/body.obj"
          ]
        }
      ]
    }
    Pose {
      children [
        DEF body Shape {
          appearance PBRAppearance {
            transparency 1
          }
          geometry Box {
            size 0.125 0.058 0.077
          }
        }
      ]
    }
  ]
  name "robot2(1)"
  boundingObject USE body
  physics Physics {
  }
  controller "follower"
}
DEF robot2 Robot {
  translation 0.899998 0.069993 0.31
  rotation 0 0 -1 -5.307179586466759e-06
  children [
    Camera {
      translation 0.06 0 0.004
      children [
        Shape {
          appearance PBRAppearance {
            transparency 1
          }
          geometry Box {
            size 0.005 0.005 0.006
          }
        }
      ]
      name "cam"
      recognition Recognition {
      }
    }
    Emitter {
      channel 1
    }
    Receiver {
      channel 1
    }
    InertialUnit {
      translation 0.021 0 0.043
      children [
        Shape {
          appearance PBRAppearance {
            baseColor 0 0.5 1
            transparency 1
          }
          geometry Box {
            size 0.01 0.01 0.01
          }
        }
      ]
      name "imu"
    }
    GPS {
      children [
        Solid {
          translation 0 0 0.041
          children [
            Shape {
              appearance PBRAppearance {
                transparency 1
              }
              geometry Cylinder {
                height 0.013
                radius 0.006
              }
            }
          ]
        }
      ]
      name "global"
    }
    DEF ds_belakang DistanceSensor {
      translation -0.0614 0 0.008
      rotation 0 0 1 3.14159
      children [
        DEF belakang Shape {
          appearance PBRAppearance {
            transparency 1
          }
          geometry Box {
            size 0.002 0.002 0.002
          }
        }
      ]
      name "ds_belakang"
      boundingObject USE belakang
      physics Physics {
      }
    }
    DEF ds_kiri DistanceSensor {
      translation -0.0089 0.0279 0.0296
      rotation 0 0 1 1.5708
      children [
        DEF kiri Shape {
          appearance PBRAppearance {
            transparency 1
          }
          geometry Box {
            size 0.002 0.002 0.002
          }
        }
      ]
      name "ds_kiri"
      boundingObject USE kiri
      physics Physics {
      }
    }
    DEF ds_kanan DistanceSensor {
      translation -0.0089 -0.0275 0.0296
      rotation 0 0 1 -1.5707953071795862
      children [
        DEF kanan Shape {
          appearance PBRAppearance {
            transparency 1
          }
          geometry Box {
            size 0.002 0.002 0.002
          }
        }
      ]
      name "ds_kanan"
      boundingObject USE kanan
      physics Physics {
      }
    }
    DEF ds_depan DistanceSensor {
      translation 0.039 0 0.03
      children [
        DEF depan Shape {
          appearance PBRAppearance {
            transparency 1
          }
          geometry Box {
            size 0.002 0.002 0.002
          }
        }
      ]
      name "ds_depan"
      boundingObject USE depan
      physics Physics {
      }
    }
    DEF motor_kanan_belakang HingeJoint {
      jointParameters HingeJointParameters {
        axis 0 1 0
        anchor -0.048 -0.0403 -0.0308
      }
      device [
        RotationalMotor {
          name "motor_kanan_belakang"
        }
        PositionSensor {
          name "encoder_4"
        }
      ]
      endPoint Solid {
        translation -0.048 -0.0403 -0.0308
        rotation 1 7.065403087751572e-16 0 1.570799999999998
        children [
          DEF roda Shape {
            appearance PBRAppearance {
              transparency 1
            }
            geometry Cylinder {
              height 0.018
              radius 0.023
            }
          }
          CadShape {
            url [
              "../../../../../../../../Downloads/swarm_obj_webots/roda_kanan_belakang.obj"
            ]
          }
        ]
        name "solid(4)"
        boundingObject USE roda
        physics Physics {
        }
      }
    }
    DEF motor_kiri_belakang HingeJoint {
      jointParameters HingeJointParameters {
        axis 0 1 0
        anchor -0.048 0.04 -0.0308
      }
      device [
        RotationalMotor {
          name "motor_kiri_belakang"
        }
        PositionSensor {
          name "encoder_3"
        }
      ]
      endPoint Solid {
        translation -0.048 0.04 -0.0308
        rotation -0.9999999999999999 3.925233147823865e-17 3.925233147823865e-17 1.5707953071795813
        children [
          DEF roda Shape {
            appearance PBRAppearance {
              transparency 1
            }
            geometry Cylinder {
              height 0.018
              radius 0.023
            }
          }
          CadShape {
            url [
              "../../../../../../../../Downloads/swarm_obj_webots/roda_kiri_belakang.obj"
            ]
          }
        ]
        name "solid(3)"
        boundingObject USE roda
        physics Physics {
        }
      }
    }
    DEF motor_kiri_depan HingeJoint {
      jointParameters HingeJointParameters {
        axis 0 1 0
        anchor 0.0251 0.04 -0.0308
      }
      device [
        RotationalMotor {
          name "motor_kiri_depan"
        }
        PositionSensor {
          name "encoder_2"
        }
      ]
      endPoint Solid {
        translation 0.0251 0.04 -0.0308
        rotation -0.9999999999999999 -1.177569944347159e-16 7.850466295647729e-17 1.5707953071795813
        children [
          DEF roda Shape {
            appearance PBRAppearance {
              transparency 1
            }
            geometry Cylinder {
              height 0.018
              radius 0.023
            }
          }
          CadShape {
            url [
              "../../../../../../../../Downloads/swarm_obj_webots/roda_kiri_depan.obj"
            ]
          }
        ]
        name "solid(2)"
        boundingObject USE roda
        physics Physics {
        }
      }
    }
    DEF motor_kanan_depan HingeJoint {
      jointParameters HingeJointParameters {
        axis 0 1 0
        anchor 0.0251 -0.0403 -0.0308
      }
      device [
        RotationalMotor {
          name "motor_kanan_depan"
        }
        PositionSensor {
          name "encoder_1"
        }
      ]
      endPoint Solid {
        translation 0.0251 -0.0403 -0.0308
        rotation 1 3.925243563834555e-17 0 1.5707899999999981
        children [
          DEF roda Shape {
            appearance PBRAppearance {
              transparency 1
            }
            geometry Cylinder {
              height 0.018
              radius 0.023
            }
          }
          CadShape {
            url [
              "../../../../../../../../Downloads/swarm_obj_webots/roda_kanan_depan.obj"
            ]
          }
        ]
        name "solid(1)"
        boundingObject USE roda
        physics Physics {
        }
      }
    }
    Solid {
      translation -0.0035 0.000126 -0.00627
      children [
        CadShape {
          url [
            "../../../../../../../../Downloads/swarm_obj_webots/body.obj"
          ]
        }
      ]
    }
    Pose {
      children [
        DEF body Shape {
          appearance PBRAppearance {
            transparency 1
          }
          geometry Box {
            size 0.125 0.058 0.077
          }
        }
      ]
    }
  ]
  name "robot2(2)"
  boundingObject USE body
  physics Physics {
  }
  controller "follower"
}
